Workbook

Sheet Overview
A1: Example Productivity Bonus Calculator | C1: 2024
B5: January | C5: February | D5: March | E5: April | F5: May | G5: June
A6: Monthly Charges | B6: =IFERROR(January!AA1,0) -> 380947 | C6: =IFERROR(February!AA1,0) -> 461379 | D6: =IFERROR(March!AA1,0) -> 415640 | E6: =IFERROR(April!AA1,0) -> 384964 | F6: =IFERROR(May!AA1,0) -> 393418 | G6: =IFERROR(June!AA1,0) -> 379996
A7: Monthly Collections | B7: =IFERROR(January!AA4,0) -> 52154 | C7: =IFERROR(February!AA4,0) -> 95666 | D7: =IFERROR(March!AA4,0) -> 66705 | E7: =IFERROR(April!AA4,0) -> 88853 | F7: =IFERROR(May!AA4,0) -> 80226 | G7: =IFERROR(June!AA4,0) -> 91729
A8: Collections Cumulative Total | B8: =B7 -> 52154 | C8: =SUM(B8,C7) -> 147820 | D8: =SUM(C8,D7) -> 214525 | E8: =SUM(D8,E7) -> 303378 | F8: =SUM(E8,F7) -> 383604 | G8: =SUM(F8,G7) -> 475333
A9: Collections Towards Bonus | B9: =IF(B8<180000,0,B8-180000) -> 0 | C9: =IF(C8<180000,0,C8-180000) -> 0 | D9: =IF(D8<180000,0,D8-180000) -> 34525 | E9: =IF(E8<180000,0,E8-180000) -> 123378 | F9: =IF(F8<180000,0,F8-180000) -> 203604 | G9: =IF(G8<180000,0,G8-180000) -> 295333
A10: Bonus:
A11: =C31 -> 0.25 | B11: =IF(B8<$A31,0,IF(B8>$B31,(($B31-$A31)*$C31),(B8-$A31)*$C31)) -> 0 | C11: =IF(C8<$A31,0,IF(C8>$B31,(($B31-$A31)*$C31),(C8-$A31)*$C31)) -> 0 | D11: =IF(D8<$A31,0,IF(D8>$B31,(($B31-$A31)*$C31),(D8-$A31)*$C31)) -> 0 | E11: =IF(E8<$A31,0,IF(E8>$B31,(($B31-$A31)*$C31),(E8-$A31)*$C31)) -> 0 | F11: =IF(F8<$A31,0,IF(F8>$B31,(($B31-$A31)*$C31),(F8-$A31)*$C31)) -> 8401 | G11: =IF(G8<$A31,0,IF(G8>$B31,(($B31-$A31)*$C31),(G8-$A31)*$C31)) -> 25000
A12: =C32 -> 0.3 | B12: =IF(B8<$A32,0,IF(B8>$B32,(($B32-$A32)*$C32),(B8-$A32)*$C32)) -> 0 | C12: =IF(C8<$A32,0,IF(C8>$B32,(($B32-$A32)*$C32),(C8-$A32)*$C32)) -> 0 | D12: =IF(D8<$A32,0,IF(D8>$B32,(($B32-$A32)*$C32),(D8-$A32)*$C32)) -> 0 | E12: =IF(E8<$A32,0,IF(E8>$B32,(($B32-$A32)*$C32),(E8-$A32)*$C32)) -> 0 | F12: =IF(F8<$A32,0,IF(F8>$B32,(($B32-$A32)*$C32),(F8-$A32)*$C32)) -> 0 | G12: =IF(G8<$A32,0,IF(G8>$B32,(($B32-$A32)*$C32),(G8-$A32)*$C32)) -> 7599.9
A13: =C33 -> 0.35 | B13: =IF(B8<$A33,0,(B8-$A33)*$C33) -> 0 | C13: =IF(C8<$A33,0,(C8-$A33)*$C33) -> 0 | D13: =IF(D8<$A33,0,(D8-$A33)*$C33) -> 0 | E13: =IF(E8<$A33,0,(E8-$A33)*$C33) -> 0 | F13: =IF(F8<$A33,0,(F8-$A33)*$C33) -> 0 | G13: =IF(G8<$A33,0,(G8-$A33)*$C33) -> 0
A14: Cumulative Bonus Earned | B14: =SUM(B11:B13) -> 0 | C14: =SUM(C11:C13) -> 0 | D14: =SUM(D11:D13) -> 0 | E14: =SUM(E11:E13) -> 0 | F14: =SUM(F11:F13) -> 8401 | G14: =SUM(G11:G13) -> 32599.9
A15: Quarterly Bonus Earned | B15: =D14 -> 0 | E15: =G14-D14 -> 32599.9
B16: July | C16: August | D16: September | E16: October | F16: November | G16: December
A17: Monthly Charges | B17: =IFERROR(July!AA1,0) -> 409615 | C17: =IFERROR(August!AA1,0) -> 418356 | D17: =IFERROR(September!AA1,0) -> 475206 | E17: =IFERROR(October!AA1,0) -> 324339 | F17: =IFERROR(November!AA1,0) -> 406041 | G17: =IFERROR(December!AA1,0) -> 444337
A18: Monthly Collections | B18: =IFERROR(July!AA4,0) -> 94535 | C18: =IFERROR(August!AA4,0) -> 63691 | D18: =IFERROR(September!AA4,0) -> 90948 | E18: =IFERROR(October!AA4,0) -> 80385 | F18: =IFERROR(November!AA4,0) -> 71910 | G18: =IFERROR(December!AA4,0) -> 77426
A19: Collections Cumulative Total | B19: =SUM(G8,B18) -> 569868 | C19: =SUM(B19,C18) -> 633559 | D19: =SUM(C19,D18) -> 724507 | E19: =SUM(D19,E18) -> 804892 | F19: =SUM(E19,F18) -> 876802 | G19: =SUM(F19,G18) -> 954228
A20: Collections Towards Bonus | B20: =IF(B19<180000,0,B19-180000) -> 389868 | C20: =IF(C19<180000,0,C19-180000) -> 453559 | D20: =IF(D19<180000,0,D19-180000) -> 544507 | E20: =IF(E19<180000,0,E19-180000) -> 624892 | F20: =IF(F19<180000,0,F19-180000) -> 696802 | G20: =IF(G19<180000,0,G19-180000) -> 774228
A21: Bonus:
A22: =C31 -> 0.25 | B22: =IF(B19<$A31,0,IF(B19>$B31,(($B31-$A31)*$C31),(B19-$A31)*$C31)) -> 25000 | C22: =IF(C19<$A31,0,IF(C19>$B31,(($B31-$A31)*$C31),(C19-$A31)*$C31)) -> 25000 | D22: =IF(D19<$A31,0,IF(D19>$B31,(($B31-$A31)*$C31),(D19-$A31)*$C31)) -> 25000 | E22: =IF(E19<$A31,0,IF(E19>$B31,(($B31-$A31)*$C31),(E19-$A31)*$C31)) -> 25000 | F22: =IF(F19<$A31,0,IF(F19>$B31,(($B31-$A31)*$C31),(F19-$A31)*$C31)) -> 25000 | G22: =IF(G19<$A31,0,IF(G19>$B31,(($B31-$A31)*$C31),(G19-$A31)*$C31)) -> 25000
A23: =C32 -> 0.3 | B23: =IF(B19<$A32,0,IF(B19>$B32,(($B32-$A32)*$C32),(B19-$A32)*$C32)) -> 35960.4 | C23: =IF(C19<$A32,0,IF(C19>$B32,(($B32-$A32)*$C32),(C19-$A32)*$C32)) -> 45000 | D23: =IF(D19<$A32,0,IF(D19>$B32,(($B32-$A32)*$C32),(D19-$A32)*$C32)) -> 45000 | E23: =IF(E19<$A32,0,IF(E19>$B32,(($B32-$A32)*$C32),(E19-$A32)*$C32)) -> 45000 | F23: =IF(F19<$A32,0,IF(F19>$B32,(($B32-$A32)*$C32),(F19-$A32)*$C32)) -> 45000 | G23: =IF(G19<$A32,0,IF(G19>$B32,(($B32-$A32)*$C32),(G19-$A32)*$C32)) -> 45000
A24: =C33 -> 0.35 | B24: =IF(B19<$A33,0,(B19-$A33)*$C33) -> 0 | C24: =IF(C19<$A33,0,(C19-$A33)*$C33) -> 11745.65 | D24: =IF(D19<$A33,0,(D19-$A33)*$C33) -> 43577.45 | E24: =IF(E19<$A33,0,(E19-$A33)*$C33) -> 71712.2 | F24: =IF(F19<$A33,0,(F19-$A33)*$C33) -> 96880.7 | G24: =IF(G19<$A33,0,(G19-$A33)*$C33) -> 123979.8
A25: Cumulative Bonus Earned | B25: =SUM(B22:B24) -> 60960.4 | C25: =SUM(C22:C24) -> 81745.65 | D25: =SUM(D22:D24) -> 113577.45 | E25: =SUM(E22:E24) -> 141712.2 | F25: =SUM(F22:F24) -> 166880.7 | G25: =SUM(G22:G24) -> 193979.8
A26: Quarterly Bonus Earned | B26: =D25-G14 -> 80977.55 | E26: =G25-D25 -> 80402.35
C28: Quarter 1 | D28: Quarter 2 | E28: Quarter 3 | F28: Quarter 4
A30: From | B30: To | C30: Bonus % | D30: Total Collections through 12/24 | E30: Calculations | G30: Cumulative Bonus earned | H30: Bonus due current period (Q4):
A31: 350000 | B31: 450000 | C31: 0.25 | D31: =G19 -> 954228 | E31: =IF(G19>B31,"("& B31& " - "& A31& ") * "& C31&" = "& G22,"("& G19&" - "& A31& ") * "& C31& " = ") -> (450000 - 350000) * 0.25 = 25000 | G31: =G25 -> 193979.8 | H31: =E26 -> 80402.35
A32: 450000 | B32: 600000 | C32: 0.3 | E32: =IF(G19>B32,"("& B32& " - "& A32& ") * "& C32& " = "& G23,IF(G19<=B31,"","("& B32& " - "& G19& ") * "& C32& " = "& G23)) -> (600000 - 450000) * 0.3 = 45000
A33: 600000 | B33: - | C33: 0.35 | E33: =IF(G19>A33,"("& G19& " - "& A33& ") * "& C33& " = "& G24,"") -> (954228 - 600000) * 0.35 = 123979.8

Sheet January
A1: Procedure Code Frequency Report | AA1: =IF(ISBLANK(A17),0,INDEX(A:A:R:R,MATCH("Total",A:A,0),MATCH("Charges",A17:R17,0))) -> 380947
U2: Page 1 of 1 | AA2: =IF(ISBLANK(A17),0,INDEX(A:A:R:R,MATCH("Total",A:A,0),MATCH("Payments",A17:R17,0))) -> 53464
AA3: =IF(ISBLANK(A17),0,INDEX(A:A:R:R,MATCH("Total",A:A,0),MATCH("Refunds",A17:R17,0))) -> 1310
U4: 45390.407 | AA4: =AA2-AA3 -> 52154
A5: Business Unit: | I5: Example
A6: Performing Provider(s): | I6: Example
A7: Billing Provider(s): | I7: ALL
G8: Location(s): | I8: ALL
C9: Billing Group(s): | I9: ALL
C10: Payer Group(s): | I10: ALL
B11: CPT Code(s): | I11: 00731, 00811, 00812, 00813, 1000F, 1036F, 3017F, 4004F, 99201, 99202, 99203, 99204, 99205, 99211, 99212, 99213, 99214, 99215, 99219, 99222, 99223, 99224, 99225, 99231, 99232, 99233, 99234, 99235, 99236, 99238, 99241, 99242, 99243, 99244, 99245, 99251, 99252, 99253, 99254, 99255, 99281, 99282, 99283, 99284, 99285, 99291, 99292, S0285, SPL, 82150, 82397, 82784, 83690, 86140, 88312, 43200, 43226, 43235, 43236, 43239, 43241, 43244, 43245, 43246, 43247, 43248, 43249, 43250, 43251, 43255, 43260, 43261, 43262, 43264, 43265, 43274, 43275, 43277, 43450, 43762, 44360, 44361, 44363, 44364, 44365, 44366, 44378, 44380, 44386, 44388, 44389, 44390, 44391, 44392, 44394, 44705, 45305, 45330, 45331, 45332, 45333, 45334, 45335, 45337, 45338, 45340, 45378, 45379, 45380, 45381, 45382, 45384, 45385, 45386, 45390, 45393, 45398, 91010, 91035, 91037, 91110, 99152, 99153, G0104, G0105, G0121, G0455
E12: Carrier(s): | I12: ALL
G13: Bill Type: | I13: Professional
D14: Cost Center(s): | H14: ALL
A15: Accounting Date From: | I15: 45292 | L15: To | N15: 45322
A17: Code | F17: Description | J17: Units | K17: Charges | M17: Payments | P17: Adjustments | R17: Refunds
A18: 99214 | F18: E/M Service Est Patient Level 4 | K18: =RANDBETWEEN(0,32500) -> 1097 | M18: =RANDBETWEEN(0,7000) -> 5123 | P18: =RANDBETWEEN(0,25000) -> 8624 | R18: =RANDBETWEEN(0,100) -> 88
A19: 99204 | F19: E/M Service New Patient Level 4 | K19: =RANDBETWEEN(0,32500) -> 22669 | M19: =RANDBETWEEN(0,7000) -> 1721 | P19: =RANDBETWEEN(0,25000) -> 10093 | R19: =RANDBETWEEN(0,100) -> 61
A20: 99223 | F20: Initial Inpatient Hospital Care Level 3 | K20: =RANDBETWEEN(0,32500) -> 14264 | M20: =RANDBETWEEN(0,7000) -> 1155 | P20: =RANDBETWEEN(0,25000) -> 12788 | R20: =RANDBETWEEN(0,100) -> 90
A21: 99233 | F21: Subsequent Hospital Care Level 3 | K21: =RANDBETWEEN(0,32500) -> 8266 | M21: =RANDBETWEEN(0,7000) -> 4096 | P21: =RANDBETWEEN(0,25000) -> 1641 | R21: =RANDBETWEEN(0,100) -> 88
A22: 99213 | F22: E/M Service Est Patient Level 3 | K22: =RANDBETWEEN(0,32500) -> 19654 | M22: =RANDBETWEEN(0,7000) -> 5295 | P22: =RANDBETWEEN(0,25000) -> 2980 | R22: =RANDBETWEEN(0,100) -> 62
A23: 99222 | F23: 1st hosp ip/obs moderate 55 | K23: =RANDBETWEEN(0,32500) -> 429 | M23: =RANDBETWEEN(0,7000) -> 1440 | P23: =RANDBETWEEN(0,25000) -> 16451 | R23: =RANDBETWEEN(0,100) -> 26
A24: 99203 | F24: E/M Service New Patient Level 3 | K24: =RANDBETWEEN(0,32500) -> 19376 | M24: =RANDBETWEEN(0,7000) -> 1570 | P24: =RANDBETWEEN(0,25000) -> 16025 | R24: =RANDBETWEEN(0,100) -> 16
A25: 99211 | F25: E/M Service Est Patient Level 1 | K25: =RANDBETWEEN(0,32500) -> 13407 | M25: =RANDBETWEEN(0,7000) -> 3645 | P25: =RANDBETWEEN(0,25000) -> 23067 | R25: =RANDBETWEEN(0,100) -> 67
A26: 99212 | F26: E/M Service Est Patient Level 2 | K26: =RANDBETWEEN(0,32500) -> 6854 | M26: =RANDBETWEEN(0,7000) -> 3544 | P26: =RANDBETWEEN(0,25000) -> 5737 | R26: =RANDBETWEEN(0,100) -> 39
A27: 99215 | F27: E/M Service Est Patient Level 5 | K27: =RANDBETWEEN(0,32500) -> 20643 | M27: =RANDBETWEEN(0,7000) -> 2255 | P27: =RANDBETWEEN(0,25000) -> 2586 | R27: =RANDBETWEEN(0,100) -> 81
A28: 99204 | F28: E/M Service New Patient Level 4 | K28: =RANDBETWEEN(0,32500) -> 9381 | M28: =RANDBETWEEN(0,7000) -> 122 | P28: =RANDBETWEEN(0,25000) -> 22642 | R28: =RANDBETWEEN(0,100) -> 32
A29: 99214 | F29: E/M Service Est Patient Level 4 | K29: =RANDBETWEEN(0,32500) -> 23002 | M29: =RANDBETWEEN(0,7000) -> 810 | P29: =RANDBETWEEN(0,25000) -> 3824 | R29: =RANDBETWEEN(0,100) -> 43
... A39: 99205 | F39: E/M Service New Patient Level 5 | K39: =RANDBETWEEN(0,32500) -> 11694 | M39: =RANDBETWEEN(0,7000) -> 5641 | P39: =RANDBETWEEN(0,25000) -> 8685 | R39: =RANDBETWEEN(0,100) -> 88
A40: Total | K40: =SUM(K18:L39) -> 380947 | M40: =SUM(M18:O39) -> 53464 | P40: =SUM(P18:Q39) -> 257989 | R40: =SUM(R18:R39) -> 1310
A41: NOTE: Total for the services column may not match the sum of totals if multiple procedure codes are present on the same superbill (to avoid counting the same superbill twice)

Sheet February
A1: Procedure Code Frequency Report | AA1: =IF(ISBLANK(A17),0,INDEX(A:A:R:R,MATCH("Total",A:A,0),MATCH("Charges",A17:R17,0))) -> 461379
U2: Page 1 of 1 | AA2: =IF(ISBLANK(A17),0,INDEX(A:A:R:R,MATCH("Total",A:A,0),MATCH("Payments",A17:R17,0))) -> 97084
AA3: =IF(ISBLANK(A17),0,INDEX(A:A:R:R,MATCH("Total",A:A,0),MATCH("Refunds",A17:R17,0))) -> 1418
U4: 45390.407 | AA4: =AA2-AA3 -> 95666
A5: Business Unit:
A6: Performing Provider(s):
A7: Billing Provider(s): | I7: ALL
G8: Location(s): | I8: ALL
C9: Billing Group(s): | I9: ALL
C10: Payer Group(s): | I10: ALL
B11: CPT Code(s): | I11: 00731, 00811, 00812, 00813, 1000F, 1036F, 3017F, 4004F, 99201, 99202, 99203, 99204, 99205, 99211, 99212, 99213, 99214, 99215, 99219, 99222, 99223, 99224, 99225, 99231, 99232, 99233, 99234, 99235, 99236, 99238, 99241, 99242, 99243, 99244, 99245, 99251, 99252, 99253, 99254, 99255, 99281, 99282, 99283, 99284, 99285, 99291, 99292, S0285, SPL, 82150, 82397, 82784, 83690, 86140, 88312, 43200, 43226, 43235, 43236, 43239, 43241, 43244, 43245, 43246, 43247, 43248, 43249, 43250, 43251, 43255, 43260, 43261, 43262, 43264, 43265, 43274, 43275, 43277, 43450, 43762, 44360, 44361, 44363, 44364, 44365, 44366, 44378, 44380, 44386, 44388, 44389, 44390, 44391, 44392, 44394, 44705, 45305, 45330, 45331, 45332, 45333, 45334, 45335, 45337, 45338, 45340, 45378, 45379, 45380, 45381, 45382, 45384, 45385, 45386, 45390, 45393, 45398, 91010, 91035, 91037, 91110, 99152, 99153, G0104, G0105, G0121, G0455
E12: Carrier(s): | I12: ALL
G13: Bill Type: | I13: Professional
D14: Cost Center(s): | H14: ALL
A15: Accounting Date From: | I15: 45323 | L15: To | N15: 45351
A17: Code | F17: Description | J17: Units | K17: Charges | M17: Payments | P17: Adjustments | R17: Refunds
A18: 99204 | F18: E/M Service New Patient Level 4 | K18: =RANDBETWEEN(0,32500) -> 9787 | M18: =RANDBETWEEN(0,7000) -> 4018 | P18: =RANDBETWEEN(0,25000) -> 21859 | R18: =RANDBETWEEN(0,100) -> 11
A19: 99214 | F19: E/M Service Est Patient Level 4 | K19: =RANDBETWEEN(0,32500) -> 19285 | M19: =RANDBETWEEN(0,7000) -> 1458 | P19: =RANDBETWEEN(0,25000) -> 11197 | R19: =RANDBETWEEN(0,100) -> 61
A20: 99233 | F20: Subsequent Hospital Care Level 3 | K20: =RANDBETWEEN(0,32500) -> 28919 | M20: =RANDBETWEEN(0,7000) -> 4691 | P20: =RANDBETWEEN(0,25000) -> 24335 | R20: =RANDBETWEEN(0,100) -> 75
A21: 99223 | F21: Initial Inpatient Hospital Care Level 3 | K21: =RANDBETWEEN(0,32500) -> 21522 | M21: =RANDBETWEEN(0,7000) -> 6231 | P21: =RANDBETWEEN(0,25000) -> 17176 | R21: =RANDBETWEEN(0,100) -> 93
A22: 99213 | F22: E/M Service Est Patient Level 3 | K22: =RANDBETWEEN(0,32500) -> 436 | M22: =RANDBETWEEN(0,7000) -> 2757 | P22: =RANDBETWEEN(0,25000) -> 9094 | R22: =RANDBETWEEN(0,100) -> 50
A23: 99203 | F23: E/M Service New Patient Level 3 | K23: =RANDBETWEEN(0,32500) -> 11388 | M23: =RANDBETWEEN(0,7000) -> 6037 | P23: =RANDBETWEEN(0,25000) -> 8845 | R23: =RANDBETWEEN(0,100) -> 58
A24: 99214 | F24: E/M Service Est Patient Level 4 | K24: =RANDBETWEEN(0,32500) -> 29791 | M24: =RANDBETWEEN(0,7000) -> 1392 | P24: =RANDBETWEEN(0,25000) -> 18642 | R24: =RANDBETWEEN(0,100) -> 84
A25: S0285 | F25: office visit before a screening colonoscopy | K25: =RANDBETWEEN(0,32500) -> 28603 | M25: =RANDBETWEEN(0,7000) -> 6775 | P25: =RANDBETWEEN(0,25000) -> 5456 | R25: =RANDBETWEEN(0,100) -> 54
A26: 99232 | F26: Subsequent Hospital Care Level 2 | K26: =RANDBETWEEN(0,32500) -> 27523 | M26: =RANDBETWEEN(0,7000) -> 5505 | P26: =RANDBETWEEN(0,25000) -> 201 | R26: =RANDBETWEEN(0,100) -> 56
A27: 99213 | F27: E/M Service Est Patient Level 3 | K27: =RANDBETWEEN(0,32500) -> 8336 | M27: =RANDBETWEEN(0,7000) -> 6285 | P27: =RANDBETWEEN(0,25000) -> 9408 | R27: =RANDBETWEEN(0,100) -> 91
A28: 86140 | F28: CRP | K28: =RANDBETWEEN(0,32500) -> 17388 | M28: =RANDBETWEEN(0,7000) -> 1949 | P28: =RANDBETWEEN(0,25000) -> 18323 | R28: =RANDBETWEEN(0,100) -> 76
A29: 83690 | F29: Lipase | K29: =RANDBETWEEN(0,32500) -> 24049 | M29: =RANDBETWEEN(0,7000) -> 3201 | P29: =RANDBETWEEN(0,25000) -> 20091 | R29: =RANDBETWEEN(0,100) -> 18
... A44: 99211 | F44: E/M Service Est Patient Level 1 | K44: =RANDBETWEEN(0,32500) -> 992 | M44: =RANDBETWEEN(0,7000) -> 6594 | P44: =RANDBETWEEN(0,25000) -> 14499 | R44: =RANDBETWEEN(0,100) -> 95
A45: Total | K45: =SUM(K18:L44) -> 461379 | M45: =SUM(M18:O44) -> 97084 | P45: =SUM(P18:Q44) -> 423781 | R45: =SUM(R18:R44) -> 1418
A46: NOTE: Total for the services column may not match the sum of totals if multiple procedure codes are present on the same superbill (to avoid counting the same superbill twice)

Sheet March
A1: Procedure Code Frequency Report | AA1: =IF(ISBLANK(A17),0,INDEX(A:A:R:R,MATCH("Total",A:A,0),MATCH("Charges",A17:R17,0))) -> 415640
U2: Page 1 of 1 | AA2: =IF(ISBLANK(A17),0,INDEX(A:A:R:R,MATCH("Total",A:A,0),MATCH("Payments",A17:R17,0))) -> 67737
AA3: =IF(ISBLANK(A17),0,INDEX(A:A:R:R,MATCH("Total",A:A,0),MATCH("Refunds",A17:R17,0))) -> 1032
U4: 45390.408 | AA4: =AA2-AA3 -> 66705
A5: Business Unit:
A6: Performing Provider(s):
A7: Billing Provider(s): | I7: ALL
G8: Location(s): | I8: ALL
C9: Billing Group(s): | I9: ALL
C10: Payer Group(s): | I10: ALL
B11: CPT Code(s): | I11: 00731, 00811, 00812, 00813, 1000F, 1036F, 3017F, 4004F, 99201, 99202, 99203, 99204, 99205, 99211, 99212, 99213, 99214, 99215, 99219, 99222, 99223, 99224, 99225, 99231, 99232, 99233, 99234, 99235, 99236, 99238, 99241, 99242, 99243, 99244, 99245, 99251, 99252, 99253, 99254, 99255, 99281, 99282, 99283, 99284, 99285, 99291, 99292, S0285, SPL, 82150, 82397, 82784, 83690, 86140, 88312, 43200, 43226, 43235, 43236, 43239, 43241, 43244, 43245, 43246, 43247, 43248, 43249, 43250, 43251, 43255, 43260, 43261, 43262, 43264, 43265, 43274, 43275, 43277, 43450, 43762, 44360, 44361, 44363, 44364, 44365, 44366, 44378, 44380, 44386, 44388, 44389, 44390, 44391, 44392, 44394, 44705, 45305, 45330, 45331, 45332, 45333, 45334, 45335, 45337, 45338, 45340, 45378, 45379, 45380, 45381, 45382, 45384, 45385, 45386, 45390, 45393, 45398, 91010, 91035, 91037, 91110, 99152, 99153, G0104, G0105, G0121, G0455
E12: Carrier(s): | I12: ALL
G13: Bill Type: | I13: Professional
D14: Cost Center(s): | H14: ALL
A15: Accounting Date From: | I15: 45352 | L15: To | N15: 45382
A17: Code | F17: Description | J17: Units | K17: Charges | M17: Payments | P17: Adjustments | R17: Refunds
A18: 99214 | F18: E/M Service Est Patient Level 4 | K18: =RANDBETWEEN(0,32500) -> 6921 | M18: =RANDBETWEEN(0,7000) -> 5109 | P18: =RANDBETWEEN(0,25000) -> 3266 | R18: =RANDBETWEEN(0,100) -> 20
A19: 99204 | F19: E/M Service New Patient Level 4 | K19: =RANDBETWEEN(0,32500) -> 30581 | M19: =RANDBETWEEN(0,7000) -> 678 | P19: =RANDBETWEEN(0,25000) -> 5347 | R19: =RANDBETWEEN(0,100) -> 69
A20: 99213 | F20: E/M Service Est Patient Level 3 | K20: =RANDBETWEEN(0,32500) -> 15827 | M20: =RANDBETWEEN(0,7000) -> 5608 | P20: =RANDBETWEEN(0,25000) -> 5147 | R20: =RANDBETWEEN(0,100) -> 12
A21: 99233 | F21: Subsequent Hospital Care Level 3 | K21: =RANDBETWEEN(0,32500) -> 2285 | M21: =RANDBETWEEN(0,7000) -> 4703 | P21: =RANDBETWEEN(0,25000) -> 17577 | R21: =RANDBETWEEN(0,100) -> 58
A22: 99223 | F22: Initial Inpatient Hospital Care Level 3 | K22: =RANDBETWEEN(0,32500) -> 24687 | M22: =RANDBETWEEN(0,7000) -> 1994 | P22: =RANDBETWEEN(0,25000) -> 195 | R22: =RANDBETWEEN(0,100) -> 23
A23: 99203 | F23: E/M Service New Patient Level 3 | K23: =RANDBETWEEN(0,32500) -> 8441 | M23: =RANDBETWEEN(0,7000) -> 2974 | P23: =RANDBETWEEN(0,25000) -> 5200 | R23: =RANDBETWEEN(0,100) -> 40
A24: S0285 | F24: office visit before a screening colonoscopy | K24: =RANDBETWEEN(0,32500) -> 24336 | M24: =RANDBETWEEN(0,7000) -> 867 | P24: =RANDBETWEEN(0,25000) -> 10428 | R24: =RANDBETWEEN(0,100) -> 8
A25: 99214 | F25: E/M Service Est Patient Level 4 | K25: =RANDBETWEEN(0,32500) -> 30103 | M25: =RANDBETWEEN(0,7000) -> 5692 | P25: =RANDBETWEEN(0,25000) -> 10787 | R25: =RANDBETWEEN(0,100) -> 55
A26: 99223 | F26: Initial Inpatient Hospital Care Level 3 | K26: =RANDBETWEEN(0,32500) -> 28990 | M26: =RANDBETWEEN(0,7000) -> 1848 | P26: =RANDBETWEEN(0,25000) -> 19302 | R26: =RANDBETWEEN(0,100) -> 59
A27: 99204 | F27: E/M Service New Patient Level 4 | K27: =RANDBETWEEN(0,32500) -> 21424 | M27: =RANDBETWEEN(0,7000) -> 4764 | P27: =RANDBETWEEN(0,25000) -> 7156 | R27: =RANDBETWEEN(0,100) -> 79
A28: 99214 | F28: E/M Service Est Patient Level 4 | K28: =RANDBETWEEN(0,32500) -> 2915 | M28: =RANDBETWEEN(0,7000) -> 1769 | P28: =RANDBETWEEN(0,25000) -> 10138 | R28: =RANDBETWEEN(0,100) -> 77
A29: 99203 | F29: E/M Service New Patient Level 3 | K29: =RANDBETWEEN(0,32500) -> 25432 | M29: =RANDBETWEEN(0,7000) -> 1199 | P29: =RANDBETWEEN(0,25000) -> 24128 | R29: =RANDBETWEEN(0,100) -> 100
... A38: 99213 | F38: E/M Service Est Patient Level 3 | K38: =RANDBETWEEN(0,32500) -> 17984 | M38: =RANDBETWEEN(0,7000) -> 430 | P38: =RANDBETWEEN(0,25000) -> 19847 | R38: =RANDBETWEEN(0,100) -> 80
A39: Total | K39: =SUM(K18:L38) -> 415640 | M39: =SUM(M18:O38) -> 67737 | P39: =SUM(P18:Q38) -> 237770 | R39: =SUM(R18:R38) -> 1032
A40: NOTE: Total for the services column may not match the sum of totals if multiple procedure codes are present on the same superbill (to avoid counting the same superbill twice)

Sheet April
A1: Procedure Code Frequency Report | AA1: =IF(ISBLANK(A17),0,INDEX(A:A:R:R,MATCH("Total",A:A,0),MATCH("Charges",A17:R17,0))) -> 384964
U2: Page 1 of 1 | AA2: =IF(ISBLANK(A17),0,INDEX(A:A:R:R,MATCH("Total",A:A,0),MATCH("Payments",A17:R17,0))) -> 90207
AA3: =IF(ISBLANK(A17),0,INDEX(A:A:R:R,MATCH("Total",A:A,0),MATCH("Refunds",A17:R17,0))) -> 1354
U4: 45483.577 | AA4: =AA2-AA3 -> 88853
A5: Business Unit:
A6: Performing Provider(s):
A7: Billing Provider(s): | I7: ALL
G8: Location(s): | I8: ALL
C9: Billing Group(s): | I9: ALL
C10: Payer Group(s): | I10: ALL
B11: CPT Code(s): | I11: 00731, 00811, 00812, 00813, 1000F, 1036F, 3017F, 4004F, 99201, 99202, 99203, 99204, 99205, 99211, 99212, 99213, 99214, 99215, 99219, 99222, 99223, 99224, 99225, 99231, 99232, 99233, 99234, 99235, 99236, 99238, 99241, 99242, 99243, 99244, 99245, 99251, 99252, 99253, 99254, 99255, 99281, 99282, 99283, 99284, 99285, 99291, 99292, S0285, SPL, 82150, 82397, 82784, 83690, 86140, 88312, 43200, 43226, 43235, 43236, 43239, 43241, 43244, 43245, 43246, 43247, 43248, 43249, 43250, 43251, 43255, 43260, 43261, 43262, 43264, 43265, 43274, 43275, 43277, 43450, 43762, 44360, 44361, 44363, 44364, 44365, 44366, 44378, 44380, 44386, 44388, 44389, 44390, 44391, 44392, 44394, 44705, 45305, 45330, 45331, 45332, 45333, 45334, 45335, 45337, 45338, 45340, 45378, 45379, 45380, 45381, 45382, 45384, 45385, 45386, 45390, 45393, 45398, 91010, 91035, 91037, 91110, 99152, 99153, G0104, G0105, G0121, G0455
E12: Carrier(s): | I12: ALL
G13: Bill Type: | I13: Professional
D14: Cost Center(s): | H14: ALL
A15: Accounting Date From: | I15: 45383 | L15: To | N15: 45412
A17: Code | F17: Description | J17: Units | K17: Charges | M17: Payments | P17: Adjustments | R17: Refunds
A18: 99204 | F18: E/M Service New Patient Level 4 | K18: =RANDBETWEEN(0,32500) -> 26814 | M18: =RANDBETWEEN(0,7000) -> 2421 | P18: =RANDBETWEEN(0,25000) -> 7251 | R18: =RANDBETWEEN(0,100) -> 15
A19: 99214 | F19: E/M Service Est Patient Level 4 | K19: =RANDBETWEEN(0,32500) -> 20457 | M19: =RANDBETWEEN(0,7000) -> 6164 | P19: =RANDBETWEEN(0,25000) -> 19423 | R19: =RANDBETWEEN(0,100) -> 66
A20: 99233 | F20: Subsequent Hospital Care Level 3 | K20: =RANDBETWEEN(0,32500) -> 10038 | M20: =RANDBETWEEN(0,7000) -> 563 | P20: =RANDBETWEEN(0,25000) -> 13342 | R20: =RANDBETWEEN(0,100) -> 13
A21: 99223 | F21: Initial Inpatient Hospital Care Level 3 | K21: =RANDBETWEEN(0,32500) -> 22824 | M21: =RANDBETWEEN(0,7000) -> 1134 | P21: =RANDBETWEEN(0,25000) -> 32 | R21: =RANDBETWEEN(0,100) -> 31
A22: 99203 | F22: E/M Service New Patient Level 3 | K22: =RANDBETWEEN(0,32500) -> 11951 | M22: =RANDBETWEEN(0,7000) -> 1178 | P22: =RANDBETWEEN(0,25000) -> 10632 | R22: =RANDBETWEEN(0,100) -> 61
A23: 99213 | F23: E/M Service Est Patient Level 3 | K23: =RANDBETWEEN(0,32500) -> 19710 | M23: =RANDBETWEEN(0,7000) -> 5778 | P23: =RANDBETWEEN(0,25000) -> 10729 | R23: =RANDBETWEEN(0,100) -> 42
A24: 99214 | F24: E/M Service Est Patient Level 4 | K24: =RANDBETWEEN(0,32500) -> 5669 | M24: =RANDBETWEEN(0,7000) -> 2461 | P24: =RANDBETWEEN(0,25000) -> 22658 | R24: =RANDBETWEEN(0,100) -> 100
A25: 99232 | F25: Subsequent Hospital Care Level 2 | K25: =RANDBETWEEN(0,32500) -> 8077 | M25: =RANDBETWEEN(0,7000) -> 6403 | P25: =RANDBETWEEN(0,25000) -> 16125 | R25: =RANDBETWEEN(0,100) -> 93
A26: 99215 | F26: E/M Service Est Patient Level 5 | K26: =RANDBETWEEN(0,32500) -> 5954 | M26: =RANDBETWEEN(0,7000) -> 3383 | P26: =RANDBETWEEN(0,25000) -> 20777 | R26: =RANDBETWEEN(0,100) -> 73
A27: 99213 | F27: E/M Service Est Patient Level 3 | K27: =RANDBETWEEN(0,32500) -> 24063 | M27: =RANDBETWEEN(0,7000) -> 984 | P27: =RANDBETWEEN(0,25000) -> 14349 | R27: =RANDBETWEEN(0,100) -> 50
A28: 99204 | F28: E/M Service New Patient Level 4 | K28: =RANDBETWEEN(0,32500) -> 3798 | M28: =RANDBETWEEN(0,7000) -> 4254 | P28: =RANDBETWEEN(0,25000) -> 659 | R28: =RANDBETWEEN(0,100) -> 18
A29: 99233 | F29: Subsequent Hospital Care Level 3 | K29: =RANDBETWEEN(0,32500) -> 8024 | M29: =RANDBETWEEN(0,7000) -> 1924 | P29: =RANDBETWEEN(0,25000) -> 10627 | R29: =RANDBETWEEN(0,100) -> 94
... A45: 99205 | F45: E/M Service New Patient Level 5 | K45: =RANDBETWEEN(0,32500) -> 31687 | M45: =RANDBETWEEN(0,7000) -> 280 | P45: =RANDBETWEEN(0,25000) -> 7110 | R45: =RANDBETWEEN(0,100) -> 16
A46: Total | K46: =SUM(K18:L45) -> 384964 | M46: =SUM(M18:O45) -> 90207 | P46: =SUM(P18:Q45) -> 367470 | R46: =SUM(R18:R45) -> 1354
A47: NOTE: Total for the services column may not match the sum of totals if multiple procedure codes are present on the same superbill (to avoid counting the same superbill twice)

Sheet May
A1: Procedure Code Frequency Report | AA1: =IF(ISBLANK(A17),0,INDEX(A:A:R:R,MATCH("Total",A:A,0),MATCH("Charges",A17:R17,0))) -> 393418
U2: Page 1 of 1 | AA2: =IF(ISBLANK(A17),0,INDEX(A:A:R:R,MATCH("Total",A:A,0),MATCH("Payments",A17:R17,0))) -> 81422
AA3: =IF(ISBLANK(A17),0,INDEX(A:A:R:R,MATCH("Total",A:A,0),MATCH("Refunds",A17:R17,0))) -> 1196
U4: 45483.577 | AA4: =AA2-AA3 -> 80226
A5: Business Unit:
A6: Performing Provider(s):
A7: Billing Provider(s): | I7: ALL
G8: Location(s): | I8: ALL
C9: Billing Group(s): | I9: ALL
C10: Payer Group(s): | I10: ALL
B11: CPT Code(s): | I11: 00731, 00811, 00812, 00813, 1000F, 1036F, 3017F, 4004F, 99201, 99202, 99203, 99204, 99205, 99211, 99212, 99213, 99214, 99215, 99219, 99222, 99223, 99224, 99225, 99231, 99232, 99233, 99234, 99235, 99236, 99238, 99241, 99242, 99243, 99244, 99245, 99251, 99252, 99253, 99254, 99255, 99281, 99282, 99283, 99284, 99285, 99291, 99292, S0285, SPL, 82150, 82397, 82784, 83690, 86140, 88312, 43200, 43226, 43235, 43236, 43239, 43241, 43244, 43245, 43246, 43247, 43248, 43249, 43250, 43251, 43255, 43260, 43261, 43262, 43264, 43265, 43274, 43275, 43277, 43450, 43762, 44360, 44361, 44363, 44364, 44365, 44366, 44378, 44380, 44386, 44388, 44389, 44390, 44391, 44392, 44394, 44705, 45305, 45330, 45331, 45332, 45333, 45334, 45335, 45337, 45338, 45340, 45378, 45379, 45380, 45381, 45382, 45384, 45385, 45386, 45390, 45393, 45398, 91010, 91035, 91037, 91110, 99152, 99153, G0104, G0105, G0121, G0455
E12: Carrier(s): | I12: ALL
G13: Bill Type: | I13: Professional
D14: Cost Center(s): | H14: ALL
A15: Accounting Date From: | I15: 45413 | L15: To | N15: 45443
A17: Code | F17: Description | J17: Units | K17: Charges | M17: Payments | P17: Adjustments | R17: Refunds
A18: 99214 | F18: E/M Service Est Patient Level 4 | K18: =RANDBETWEEN(0,32500) -> 24713 | M18: =RANDBETWEEN(0,7000) -> 6634 | P18: =RANDBETWEEN(0,25000) -> 8032 | R18: =RANDBETWEEN(0,100) -> 10
A19: 99204 | F19: E/M Service New Patient Level 4 | K19: =RANDBETWEEN(0,32500) -> 29028 | M19: =RANDBETWEEN(0,7000) -> 5413 | P19: =RANDBETWEEN(0,25000) -> 13872 | R19: =RANDBETWEEN(0,100) -> 29
A20: 99233 | F20: Subsequent Hospital Care Level 3 | K20: =RANDBETWEEN(0,32500) -> 6356 | M20: =RANDBETWEEN(0,7000) -> 917 | P20: =RANDBETWEEN(0,25000) -> 22031 | R20: =RANDBETWEEN(0,100) -> 78
A21: 99223 | F21: Initial Inpatient Hospital Care Level 3 | K21: =RANDBETWEEN(0,32500) -> 12248 | M21: =RANDBETWEEN(0,7000) -> 5437 | P21: =RANDBETWEEN(0,25000) -> 11097 | R21: =RANDBETWEEN(0,100) -> 24
A22: 99222 | F22: 1st hosp ip/obs moderate 55 | K22: =RANDBETWEEN(0,32500) -> 5482 | M22: =RANDBETWEEN(0,7000) -> 229 | P22: =RANDBETWEEN(0,25000) -> 17565 | R22: =RANDBETWEEN(0,100) -> 44
A23: 99203 | F23: E/M Service New Patient Level 3 | K23: =RANDBETWEEN(0,32500) -> 6253 | M23: =RANDBETWEEN(0,7000) -> 2285 | P23: =RANDBETWEEN(0,25000) -> 4455 | R23: =RANDBETWEEN(0,100) -> 17
A24: 99213 | F24: E/M Service Est Patient Level 3 | K24: =RANDBETWEEN(0,32500) -> 4878 | M24: =RANDBETWEEN(0,7000) -> 5678 | P24: =RANDBETWEEN(0,25000) -> 21470 | R24: =RANDBETWEEN(0,100) -> 68
A25: 99214 | F25: E/M Service Est Patient Level 4 | K25: =RANDBETWEEN(0,32500) -> 3081 | M25: =RANDBETWEEN(0,7000) -> 1240 | P25: =RANDBETWEEN(0,25000) -> 12230 | R25: =RANDBETWEEN(0,100) -> 23
A26: 99254 | F26: Initial Inpatient Consult Level 4 | K26: =RANDBETWEEN(0,32500) -> 18299 | M26: =RANDBETWEEN(0,7000) -> 6555 | P26: =RANDBETWEEN(0,25000) -> 8415 | R26: =RANDBETWEEN(0,100) -> 89
A27: 99233 | F27: Subsequent Hospital Care Level 3 | K27: =RANDBETWEEN(0,32500) -> 29827 | M27: =RANDBETWEEN(0,7000) -> 2350 | P27: =RANDBETWEEN(0,25000) -> 16237 | R27: =RANDBETWEEN(0,100) -> 90
A28: 99223 | F28: Initial Inpatient Hospital Care Level 3 | K28: =RANDBETWEEN(0,32500) -> 12713 | M28: =RANDBETWEEN(0,7000) -> 3738 | P28: =RANDBETWEEN(0,25000) -> 12962 | R28: =RANDBETWEEN(0,100) -> 95
A29: 99204 | F29: E/M Service New Patient Level 4 | K29: =RANDBETWEEN(0,32500) -> 18482 | M29: =RANDBETWEEN(0,7000) -> 3197 | P29: =RANDBETWEEN(0,25000) -> 6337 | R29: =RANDBETWEEN(0,100) -> 35
... A41: 99214 | F41: E/M Service Est Patient Level 4 | K41: =RANDBETWEEN(0,32500) -> 20429 | M41: =RANDBETWEEN(0,7000) -> 3931 | P41: =RANDBETWEEN(0,25000) -> 10041 | R41: =RANDBETWEEN(0,100) -> 48
A42: Total | K42: =SUM(K18:L41) -> 393418 | M42: =SUM(M18:O41) -> 81422 | P42: =SUM(P18:Q41) -> 303077 | R42: =SUM(R18:R41) -> 1196
A43: NOTE: Total for the services column may not match the sum of totals if multiple procedure codes are present on the same superbill (to avoid counting the same superbill twice)

Sheet June
A1: Procedure Code Frequency Report | AA1: =IF(ISBLANK(A17),0,INDEX(A:A:R:R,MATCH("Total",A:A,0),MATCH("Charges",A17:R17,0))) -> 379996
U2: Page 1 of 1 | AA2: =IF(ISBLANK(A17),0,INDEX(A:A:R:R,MATCH("Total",A:A,0),MATCH("Payments",A17:R17,0))) -> 93180
AA3: =IF(ISBLANK(A17),0,INDEX(A:A:R:R,MATCH("Total",A:A,0),MATCH("Refunds",A17:R17,0))) -> 1451
U4: 45483.578 | AA4: =AA2-AA3 -> 91729
A5: Business Unit:
A6: Performing Provider(s):
A7: Billing Provider(s): | I7: ALL
G8: Location(s): | I8: ALL
C9: Billing Group(s): | I9: ALL
C10: Payer Group(s): | I10: ALL
B11: CPT Code(s): | I11: 00731, 00811, 00812, 00813, 1000F, 1036F, 3017F, 4004F, 99201, 99202, 99203, 99204, 99205, 99211, 99212, 99213, 99214, 99215, 99219, 99222, 99223, 99224, 99225, 99231, 99232, 99233, 99234, 99235, 99236, 99238, 99241, 99242, 99243, 99244, 99245, 99251, 99252, 99253, 99254, 99255, 99281, 99282, 99283, 99284, 99285, 99291, 99292, S0285, SPL, 82150, 82397, 82784, 83690, 86140, 88312, 43200, 43226, 43235, 43236, 43239, 43241, 43244, 43245, 43246, 43247, 43248, 43249, 43250, 43251, 43255, 43260, 43261, 43262, 43264, 43265, 43274, 43275, 43277, 43450, 43762, 44360, 44361, 44363, 44364, 44365, 44366, 44378, 44380, 44386, 44388, 44389, 44390, 44391, 44392, 44394, 44705, 45305, 45330, 45331, 45332, 45333, 45334, 45335, 45337, 45338, 45340, 45378, 45379, 45380, 45381, 45382, 45384, 45385, 45386, 45390, 45393, 45398, 91010, 91035, 91037, 91110, 99152, 99153, G0104, G0105, G0121, G0455
E12: Carrier(s): | I12: ALL
G13: Bill Type: | I13: Professional
D14: Cost Center(s): | H14: ALL
A15: Accounting Date From: | I15: 45444 | L15: To | N15: 45473
A17: Code | F17: Description | J17: Units | K17: Charges | M17: Payments | P17: Adjustments | R17: Refunds
A18: 99214 | F18: E/M Service Est Patient Level 4 | K18: =RANDBETWEEN(0,32500) -> 8635 | M18: =RANDBETWEEN(0,7000) -> 4540 | P18: =RANDBETWEEN(0,25000) -> 7136 | R18: =RANDBETWEEN(0,100) -> 99
A19: 99204 | F19: E/M Service New Patient Level 4 | K19: =RANDBETWEEN(0,32500) -> 7386 | M19: =RANDBETWEEN(0,7000) -> 3001 | P19: =RANDBETWEEN(0,25000) -> 21249 | R19: =RANDBETWEEN(0,100) -> 91
A20: 99233 | F20: Subsequent Hospital Care Level 3 | K20: =RANDBETWEEN(0,32500) -> 26363 | M20: =RANDBETWEEN(0,7000) -> 1790 | P20: =RANDBETWEEN(0,25000) -> 8438 | R20: =RANDBETWEEN(0,100) -> 16
A21: 99223 | F21: Initial Inpatient Hospital Care Level 3 | K21: =RANDBETWEEN(0,32500) -> 31226 | M21: =RANDBETWEEN(0,7000) -> 3437 | P21: =RANDBETWEEN(0,25000) -> 14047 | R21: =RANDBETWEEN(0,100) -> 68
A22: 99203 | F22: E/M Service New Patient Level 3 | K22: =RANDBETWEEN(0,32500) -> 23360 | M22: =RANDBETWEEN(0,7000) -> 4218 | P22: =RANDBETWEEN(0,25000) -> 19638 | R22: =RANDBETWEEN(0,100) -> 58
A23: 99222 | F23: 1st hosp ip/obs moderate 55 | K23: =RANDBETWEEN(0,32500) -> 26253 | M23: =RANDBETWEEN(0,7000) -> 3708 | P23: =RANDBETWEEN(0,25000) -> 18455 | R23: =RANDBETWEEN(0,100) -> 62
A24: 99213 | F24: E/M Service Est Patient Level 3 | K24: =RANDBETWEEN(0,32500) -> 17315 | M24: =RANDBETWEEN(0,7000) -> 4001 | P24: =RANDBETWEEN(0,25000) -> 7063 | R24: =RANDBETWEEN(0,100) -> 92
A25: 99254 | F25: Initial Inpatient Consult Level 4 | K25: =RANDBETWEEN(0,32500) -> 9575 | M25: =RANDBETWEEN(0,7000) -> 1000 | P25: =RANDBETWEEN(0,25000) -> 16549 | R25: =RANDBETWEEN(0,100) -> 63
A26: 99214 | F26: E/M Service Est Patient Level 4 | K26: =RANDBETWEEN(0,32500) -> 6432 | M26: =RANDBETWEEN(0,7000) -> 5658 | P26: =RANDBETWEEN(0,25000) -> 2778 | R26: =RANDBETWEEN(0,100) -> 27
A27: 99213 | F27: E/M Service Est Patient Level 3 | K27: =RANDBETWEEN(0,32500) -> 3927 | M27: =RANDBETWEEN(0,7000) -> 4783 | P27: =RANDBETWEEN(0,25000) -> 5667 | R27: =RANDBETWEEN(0,100) -> 41
A28: S0285 | F28: office visit before a screening colonoscopy | K28: =RANDBETWEEN(0,32500) -> 11627 | M28: =RANDBETWEEN(0,7000) -> 5938 | P28: =RANDBETWEEN(0,25000) -> 12509 | R28: =RANDBETWEEN(0,100) -> 14
A29: 99204 | F29: E/M Service New Patient Level 4 | K29: =RANDBETWEEN(0,32500) -> 16331 | M29: =RANDBETWEEN(0,7000) -> 6562 | P29: =RANDBETWEEN(0,25000) -> 13703 | R29: =RANDBETWEEN(0,100) -> 84
... A42: 99233 | F42: Subsequent Hospital Care Level 3 | K42: =RANDBETWEEN(0,32500) -> 12307 | M42: =RANDBETWEEN(0,7000) -> 800 | P42: =RANDBETWEEN(0,25000) -> 11486 | R42: =RANDBETWEEN(0,100) -> 4
A43: Total | K43: =SUM(K18:L42) -> 379996 | M43: =SUM(M18:O42) -> 93180 | P43: =SUM(P18:Q42) -> 306345 | R43: =SUM(R18:R42) -> 1451
A44: NOTE: Total for the services column may not match the sum of totals if multiple procedure codes are present on the same superbill (to avoid counting the same superbill twice)

Sheet July
A1: Procedure Code Frequency Report | AA1: =IF(ISBLANK(A17),0,INDEX(A:A:R:R,MATCH("Total",A:A,0),MATCH("Charges",A17:R17,0))) -> 409615
U2: Page 1 of 1 | AA2: =IF(ISBLANK(A17),0,INDEX(A:A:R:R,MATCH("Total",A:A,0),MATCH("Payments",A17:R17,0))) -> 95968
AA3: =IF(ISBLANK(A17),0,INDEX(A:A:R:R,MATCH("Total",A:A,0),MATCH("Refunds",A17:R17,0))) -> 1433
AA4: =AA2-AA3 -> 94535
A5: Business Unit:
A6: Performing Provider(s):
A7: Billing Provider(s): | I7: ALL
G8: Location(s): | I8: ALL
C9: Billing Group(s): | I9: ALL
C10: Payer Group(s): | I10: ALL
B11: CPT Code(s): | I11: 00731, 00811, 00812, 00813, 1000F, 1036F, 3017F, 4004F, 99201, 99202, 99203, 99204, 99205, 99211, 99212, 99213, 99214, 99215, 99219, 99222, 99223, 99224, 99225, 99231, 99232, 99233, 99234, 99235, 99236, 99238, 99241, 99242, 99243, 99244, 99245, 99251, 99252, 99253, 99254, 99255, 99281, 99282, 99283, 99284, 99285, 99291, 99292, S0285, SPL, 82150, 82397, 82784, 83690, 86140, 88312, 43200, 43226, 43235, 43236, 43239, 43241, 43244, 43245, 43246, 43247, 43248, 43249, 43250, 43251, 43255, 43260, 43261, 43262, 43264, 43265, 43274, 43275, 43277, 43450, 43762, 44360, 44361, 44363, 44364, 44365, 44366, 44378, 44380, 44386, 44388, 44389, 44390, 44391, 44392, 44394, 44705, 45305, 45330, 45331, 45332, 45333, 45334, 45335, 45337, 45338, 45340, 45378, 45379, 45380, 45381, 45382, 45384, 45385, 45386, 45390, 45393, 45398, 91010, 91035, 91037, 91110, 99152, 99153, G0104, G0105, G0121, G0455
E12: Carrier(s): | I12: ALL
G13: Bill Type: | I13: Professional
D14: Cost Center(s): | H14: ALL
A15: Accounting Date From: | I15: 45474 | L15: To | N15: 45503
A17: Code | F17: Description | J17: Units | K17: Charges | M17: Payments | P17: Adjustments | R17: Refunds
A18: 99214 | F18: E/M Service Est Patient Level 4 | K18: =RANDBETWEEN(0,32500) -> 23898 | M18: =RANDBETWEEN(0,7000) -> 939 | P18: =RANDBETWEEN(0,25000) -> 12270 | R18: =RANDBETWEEN(0,100) -> 25
A19: 99204 | F19: E/M Service New Patient Level 4 | K19: =RANDBETWEEN(0,32500) -> 12095 | M19: =RANDBETWEEN(0,7000) -> 2675 | P19: =RANDBETWEEN(0,25000) -> 21401 | R19: =RANDBETWEEN(0,100) -> 3
A20: 99233 | F20: Subsequent Hospital Care Level 3 | K20: =RANDBETWEEN(0,32500) -> 23737 | M20: =RANDBETWEEN(0,7000) -> 4790 | P20: =RANDBETWEEN(0,25000) -> 1386 | R20: =RANDBETWEEN(0,100) -> 58
A21: 99223 | F21: Initial Inpatient Hospital Care Level 3 | K21: =RANDBETWEEN(0,32500) -> 29860 | M21: =RANDBETWEEN(0,7000) -> 3133 | P21: =RANDBETWEEN(0,25000) -> 13299 | R21: =RANDBETWEEN(0,100) -> 23
A22: 99203 | F22: E/M Service New Patient Level 3 | K22: =RANDBETWEEN(0,32500) -> 7385 | M22: =RANDBETWEEN(0,7000) -> 6858 | P22: =RANDBETWEEN(0,25000) -> 4091 | R22: =RANDBETWEEN(0,100) -> 55
A23: 99222 | F23: 1st hosp ip/obs moderate 55 | K23: =RANDBETWEEN(0,32500) -> 4497 | M23: =RANDBETWEEN(0,7000) -> 564 | P23: =RANDBETWEEN(0,25000) -> 6231 | R23: =RANDBETWEEN(0,100) -> 100
A24: 99213 | F24: E/M Service Est Patient Level 3 | K24: =RANDBETWEEN(0,32500) -> 22109 | M24: =RANDBETWEEN(0,7000) -> 6514 | P24: =RANDBETWEEN(0,25000) -> 14261 | R24: =RANDBETWEEN(0,100) -> 37
A25: 99254 | F25: Initial Inpatient Consult Level 4 | K25: =RANDBETWEEN(0,32500) -> 4962 | M25: =RANDBETWEEN(0,7000) -> 6590 | P25: =RANDBETWEEN(0,25000) -> 781 | R25: =RANDBETWEEN(0,100) -> 55
A26: 99214 | F26: E/M Service Est Patient Level 4 | K26: =RANDBETWEEN(0,32500) -> 29567 | M26: =RANDBETWEEN(0,7000) -> 6663 | P26: =RANDBETWEEN(0,25000) -> 110 | R26: =RANDBETWEEN(0,100) -> 25
A27: 99213 | F27: E/M Service Est Patient Level 3 | K27: =RANDBETWEEN(0,32500) -> 32500 | M27: =RANDBETWEEN(0,7000) -> 4560 | P27: =RANDBETWEEN(0,25000) -> 11550 | R27: =RANDBETWEEN(0,100) -> 63
A28: S0285 | F28: office visit before a screening colonoscopy | K28: =RANDBETWEEN(0,32500) -> 2635 | M28: =RANDBETWEEN(0,7000) -> 73 | P28: =RANDBETWEEN(0,25000) -> 13640 | R28: =RANDBETWEEN(0,100) -> 84
A29: 99204 | F29: E/M Service New Patient Level 4 | K29: =RANDBETWEEN(0,32500) -> 2319 | M29: =RANDBETWEEN(0,7000) -> 6962 | P29: =RANDBETWEEN(0,25000) -> 6310 | R29: =RANDBETWEEN(0,100) -> 51
... A42: 99233 | F42: Subsequent Hospital Care Level 3 | K42: =RANDBETWEEN(0,32500) -> 13084 | M42: =RANDBETWEEN(0,7000) -> 1316 | P42: =RANDBETWEEN(0,25000) -> 6937 | R42: =RANDBETWEEN(0,100) -> 0
A43: Total | K43: =SUM(K18:L42) -> 409615 | M43: =SUM(M18:O42) -> 95968 | P43: =SUM(P18:Q42) -> 248182 | R43: =SUM(R18:R42) -> 1433
A44: NOTE: Total for the services column may not match the sum of totals if multiple procedure codes are present on the same superbill (to avoid counting the same superbill twice)

Sheet August
A1: Procedure Code Frequency Report | AA1: =IF(ISBLANK(A17),0,INDEX(A:A:R:R,MATCH("Total",A:A,0),MATCH("Charges",A17:R17,0))) -> 418356
U2: Page 1 of 1 | AA2: =IF(ISBLANK(A17),0,INDEX(A:A:R:R,MATCH("Total",A:A,0),MATCH("Payments",A17:R17,0))) -> 64992
AA3: =IF(ISBLANK(A17),0,INDEX(A:A:R:R,MATCH("Total",A:A,0),MATCH("Refunds",A17:R17,0))) -> 1301
AA4: =AA2-AA3 -> 63691
A5: Business Unit:
A6: Performing Provider(s):
A7: Billing Provider(s): | I7: ALL
G8: Location(s): | I8: ALL
C9: Billing Group(s): | I9: ALL
C10: Payer Group(s): | I10: ALL
B11: CPT Code(s): | I11: 00731, 00811, 00812, 00813, 1000F, 1036F, 3017F, 4004F, 99201, 99202, 99203, 99204, 99205, 99211, 99212, 99213, 99214, 99215, 99219, 99222, 99223, 99224, 99225, 99231, 99232, 99233, 99234, 99235, 99236, 99238, 99241, 99242, 99243, 99244, 99245, 99251, 99252, 99253, 99254, 99255, 99281, 99282, 99283, 99284, 99285, 99291, 99292, S0285, SPL, 82150, 82397, 82784, 83690, 86140, 88312, 43200, 43226, 43235, 43236, 43239, 43241, 43244, 43245, 43246, 43247, 43248, 43249, 43250, 43251, 43255, 43260, 43261, 43262, 43264, 43265, 43274, 43275, 43277, 43450, 43762, 44360, 44361, 44363, 44364, 44365, 44366, 44378, 44380, 44386, 44388, 44389, 44390, 44391, 44392, 44394, 44705, 45305, 45330, 45331, 45332, 45333, 45334, 45335, 45337, 45338, 45340, 45378, 45379, 45380, 45381, 45382, 45384, 45385, 45386, 45390, 45393, 45398, 91010, 91035, 91037, 91110, 99152, 99153, G0104, G0105, G0121, G0455
E12: Carrier(s): | I12: ALL
G13: Bill Type: | I13: Professional
D14: Cost Center(s): | H14: ALL
A15: Accounting Date From: | I15: 45505 | L15: To | N15: 45534
A17: Code | F17: Description | J17: Units | K17: Charges | M17: Payments | P17: Adjustments | R17: Refunds
A18: 99214 | F18: E/M Service Est Patient Level 4 | K18: =RANDBETWEEN(0,32500) -> 6201 | M18: =RANDBETWEEN(0,7000) -> 1831 | P18: =RANDBETWEEN(0,25000) -> 8022 | R18: =RANDBETWEEN(0,100) -> 95
A19: 99204 | F19: E/M Service New Patient Level 4 | K19: =RANDBETWEEN(0,32500) -> 8296 | M19: =RANDBETWEEN(0,7000) -> 4643 | P19: =RANDBETWEEN(0,25000) -> 23576 | R19: =RANDBETWEEN(0,100) -> 23
A20: 99233 | F20: Subsequent Hospital Care Level 3 | K20: =RANDBETWEEN(0,32500) -> 12305 | M20: =RANDBETWEEN(0,7000) -> 835 | P20: =RANDBETWEEN(0,25000) -> 10618 | R20: =RANDBETWEEN(0,100) -> 33
A21: 99223 | F21: Initial Inpatient Hospital Care Level 3 | K21: =RANDBETWEEN(0,32500) -> 32210 | M21: =RANDBETWEEN(0,7000) -> 2183 | P21: =RANDBETWEEN(0,25000) -> 12698 | R21: =RANDBETWEEN(0,100) -> 20
A22: 99203 | F22: E/M Service New Patient Level 3 | K22: =RANDBETWEEN(0,32500) -> 26179 | M22: =RANDBETWEEN(0,7000) -> 6315 | P22: =RANDBETWEEN(0,25000) -> 11148 | R22: =RANDBETWEEN(0,100) -> 30
A23: 99222 | F23: 1st hosp ip/obs moderate 55 | K23: =RANDBETWEEN(0,32500) -> 16566 | M23: =RANDBETWEEN(0,7000) -> 2787 | P23: =RANDBETWEEN(0,25000) -> 16004 | R23: =RANDBETWEEN(0,100) -> 72
A24: 99213 | F24: E/M Service Est Patient Level 3 | K24: =RANDBETWEEN(0,32500) -> 11774 | M24: =RANDBETWEEN(0,7000) -> 5148 | P24: =RANDBETWEEN(0,25000) -> 18228 | R24: =RANDBETWEEN(0,100) -> 88
A25: 99254 | F25: Initial Inpatient Consult Level 4 | K25: =RANDBETWEEN(0,32500) -> 5527 | M25: =RANDBETWEEN(0,7000) -> 2114 | P25: =RANDBETWEEN(0,25000) -> 17818 | R25: =RANDBETWEEN(0,100) -> 35
A26: 99214 | F26: E/M Service Est Patient Level 4 | K26: =RANDBETWEEN(0,32500) -> 685 | M26: =RANDBETWEEN(0,7000) -> 847 | P26: =RANDBETWEEN(0,25000) -> 6526 | R26: =RANDBETWEEN(0,100) -> 77
A27: 99213 | F27: E/M Service Est Patient Level 3 | K27: =RANDBETWEEN(0,32500) -> 12929 | M27: =RANDBETWEEN(0,7000) -> 3120 | P27: =RANDBETWEEN(0,25000) -> 21979 | R27: =RANDBETWEEN(0,100) -> 71
A28: S0285 | F28: office visit before a screening colonoscopy | K28: =RANDBETWEEN(0,32500) -> 20355 | M28: =RANDBETWEEN(0,7000) -> 2844 | P28: =RANDBETWEEN(0,25000) -> 21874 | R28: =RANDBETWEEN(0,100) -> 81
A29: 99204 | F29: E/M Service New Patient Level 4 | K29: =RANDBETWEEN(0,32500) -> 30680 | M29: =RANDBETWEEN(0,7000) -> 1380 | P29: =RANDBETWEEN(0,25000) -> 22266 | R29: =RANDBETWEEN(0,100) -> 66
... A42: 99233 | F42: Subsequent Hospital Care Level 3 | K42: =RANDBETWEEN(0,32500) -> 28541 | M42: =RANDBETWEEN(0,7000) -> 1000 | P42: =RANDBETWEEN(0,25000) -> 15568 | R42: =RANDBETWEEN(0,100) -> 84
A43: Total | K43: =SUM(K18:L42) -> 418356 | M43: =SUM(M18:O42) -> 64992 | P43: =SUM(P18:Q42) -> 365881 | R43: =SUM(R18:R42) -> 1301
A44: NOTE: Total for the services column may not match the sum of totals if multiple procedure codes are present on the same superbill (to avoid counting the same superbill twice)

Sheet September
A1: Procedure Code Frequency Report | AA1: =IF(ISBLANK(A17),0,INDEX(A:A:R:R,MATCH("Total",A:A,0),MATCH("Charges",A17:R17,0))) -> 475206
U2: Page 1 of 1 | AA2: =IF(ISBLANK(A17),0,INDEX(A:A:R:R,MATCH("Total",A:A,0),MATCH("Payments",A17:R17,0))) -> 92284
AA3: =IF(ISBLANK(A17),0,INDEX(A:A:R:R,MATCH("Total",A:A,0),MATCH("Refunds",A17:R17,0))) -> 1336
AA4: =AA2-AA3 -> 90948
A5: Business Unit:
A6: Performing Provider(s):
A7: Billing Provider(s): | I7: ALL
G8: Location(s): | I8: ALL
C9: Billing Group(s): | I9: ALL
C10: Payer Group(s): | I10: ALL
B11: CPT Code(s): | I11: 00731, 00811, 00812, 00813, 1000F, 1036F, 3017F, 4004F, 99201, 99202, 99203, 99204, 99205, 99211, 99212, 99213, 99214, 99215, 99219, 99222, 99223, 99224, 99225, 99231, 99232, 99233, 99234, 99235, 99236, 99238, 99241, 99242, 99243, 99244, 99245, 99251, 99252, 99253, 99254, 99255, 99281, 99282, 99283, 99284, 99285, 99291, 99292, S0285, SPL, 82150, 82397, 82784, 83690, 86140, 88312, 43200, 43226, 43235, 43236, 43239, 43241, 43244, 43245, 43246, 43247, 43248, 43249, 43250, 43251, 43255, 43260, 43261, 43262, 43264, 43265, 43274, 43275, 43277, 43450, 43762, 44360, 44361, 44363, 44364, 44365, 44366, 44378, 44380, 44386, 44388, 44389, 44390, 44391, 44392, 44394, 44705, 45305, 45330, 45331, 45332, 45333, 45334, 45335, 45337, 45338, 45340, 45378, 45379, 45380, 45381, 45382, 45384, 45385, 45386, 45390, 45393, 45398, 91010, 91035, 91037, 91110, 99152, 99153, G0104, G0105, G0121, G0455
E12: Carrier(s): | I12: ALL
G13: Bill Type: | I13: Professional
D14: Cost Center(s): | H14: ALL
A15: Accounting Date From: | I15: 45536 | L15: To | N15: 45565
A17: Code | F17: Description | J17: Units | K17: Charges | M17: Payments | P17: Adjustments | R17: Refunds
A18: 99214 | F18: E/M Service Est Patient Level 4 | K18: =RANDBETWEEN(0,32500) -> 20494 | M18: =RANDBETWEEN(0,7000) -> 2325 | P18: =RANDBETWEEN(0,25000) -> 16508 | R18: =RANDBETWEEN(0,100) -> 67
A19: 99204 | F19: E/M Service New Patient Level 4 | K19: =RANDBETWEEN(0,32500) -> 14053 | M19: =RANDBETWEEN(0,7000) -> 5780 | P19: =RANDBETWEEN(0,25000) -> 21006 | R19: =RANDBETWEEN(0,100) -> 74
A20: 99233 | F20: Subsequent Hospital Care Level 3 | K20: =RANDBETWEEN(0,32500) -> 23994 | M20: =RANDBETWEEN(0,7000) -> 4269 | P20: =RANDBETWEEN(0,25000) -> 16708 | R20: =RANDBETWEEN(0,100) -> 58
A21: 99223 | F21: Initial Inpatient Hospital Care Level 3 | K21: =RANDBETWEEN(0,32500) -> 23038 | M21: =RANDBETWEEN(0,7000) -> 134 | P21: =RANDBETWEEN(0,25000) -> 24209 | R21: =RANDBETWEEN(0,100) -> 97
A22: 99203 | F22: E/M Service New Patient Level 3 | K22: =RANDBETWEEN(0,32500) -> 29809 | M22: =RANDBETWEEN(0,7000) -> 5005 | P22: =RANDBETWEEN(0,25000) -> 2107 | R22: =RANDBETWEEN(0,100) -> 16
A23: 99222 | F23: 1st hosp ip/obs moderate 55 | K23: =RANDBETWEEN(0,32500) -> 26616 | M23: =RANDBETWEEN(0,7000) -> 5996 | P23: =RANDBETWEEN(0,25000) -> 12869 | R23: =RANDBETWEEN(0,100) -> 100
A24: 99213 | F24: E/M Service Est Patient Level 3 | K24: =RANDBETWEEN(0,32500) -> 26487 | M24: =RANDBETWEEN(0,7000) -> 5149 | P24: =RANDBETWEEN(0,25000) -> 2521 | R24: =RANDBETWEEN(0,100) -> 95
A25: 99254 | F25: Initial Inpatient Consult Level 4 | K25: =RANDBETWEEN(0,32500) -> 6872 | M25: =RANDBETWEEN(0,7000) -> 6942 | P25: =RANDBETWEEN(0,25000) -> 19608 | R25: =RANDBETWEEN(0,100) -> 76
A26: 99214 | F26: E/M Service Est Patient Level 4 | K26: =RANDBETWEEN(0,32500) -> 19231 | M26: =RANDBETWEEN(0,7000) -> 4877 | P26: =RANDBETWEEN(0,25000) -> 6923 | R26: =RANDBETWEEN(0,100) -> 3
A27: 99213 | F27: E/M Service Est Patient Level 3 | K27: =RANDBETWEEN(0,32500) -> 1504 | M27: =RANDBETWEEN(0,7000) -> 4099 | P27: =RANDBETWEEN(0,25000) -> 23662 | R27: =RANDBETWEEN(0,100) -> 54
A28: S0285 | F28: office visit before a screening colonoscopy | K28: =RANDBETWEEN(0,32500) -> 28789 | M28: =RANDBETWEEN(0,7000) -> 5640 | P28: =RANDBETWEEN(0,25000) -> 7516 | R28: =RANDBETWEEN(0,100) -> 3
A29: 99204 | F29: E/M Service New Patient Level 4 | K29: =RANDBETWEEN(0,32500) -> 2276 | M29: =RANDBETWEEN(0,7000) -> 967 | P29: =RANDBETWEEN(0,25000) -> 7836 | R29: =RANDBETWEEN(0,100) -> 83
... A42: 99233 | F42: Subsequent Hospital Care Level 3 | K42: =RANDBETWEEN(0,32500) -> 10914 | M42: =RANDBETWEEN(0,7000) -> 5313 | P42: =RANDBETWEEN(0,25000) -> 13800 | R42: =RANDBETWEEN(0,100) -> 96
A43: Total | K43: =SUM(K18:L42) -> 475206 | M43: =SUM(M18:O42) -> 92284 | P43: =SUM(P18:Q42) -> 328142 | R43: =SUM(R18:R42) -> 1336
A44: NOTE: Total for the services column may not match the sum of totals if multiple procedure codes are present on the same superbill (to avoid counting the same superbill twice)

Sheet October
A1: Procedure Code Frequency Report | AA1: =IF(ISBLANK(A17),0,INDEX(A:A:R:R,MATCH("Total",A:A,0),MATCH("Charges",A17:R17,0))) -> 324339
U2: Page 1 of 1 | AA2: =IF(ISBLANK(A17),0,INDEX(A:A:R:R,MATCH("Total",A:A,0),MATCH("Payments",A17:R17,0))) -> 81650
AA3: =IF(ISBLANK(A17),0,INDEX(A:A:R:R,MATCH("Total",A:A,0),MATCH("Refunds",A17:R17,0))) -> 1265
AA4: =AA2-AA3 -> 80385
A5: Business Unit:
A6: Performing Provider(s):
A7: Billing Provider(s): | I7: ALL
G8: Location(s): | I8: ALL
C9: Billing Group(s): | I9: ALL
C10: Payer Group(s): | I10: ALL
B11: CPT Code(s): | I11: 00731, 00811, 00812, 00813, 1000F, 1036F, 3017F, 4004F, 99201, 99202, 99203, 99204, 99205, 99211, 99212, 99213, 99214, 99215, 99219, 99222, 99223, 99224, 99225, 99231, 99232, 99233, 99234, 99235, 99236, 99238, 99241, 99242, 99243, 99244, 99245, 99251, 99252, 99253, 99254, 99255, 99281, 99282, 99283, 99284, 99285, 99291, 99292, S0285, SPL, 82150, 82397, 82784, 83690, 86140, 88312, 43200, 43226, 43235, 43236, 43239, 43241, 43244, 43245, 43246, 43247, 43248, 43249, 43250, 43251, 43255, 43260, 43261, 43262, 43264, 43265, 43274, 43275, 43277, 43450, 43762, 44360, 44361, 44363, 44364, 44365, 44366, 44378, 44380, 44386, 44388, 44389, 44390, 44391, 44392, 44394, 44705, 45305, 45330, 45331, 45332, 45333, 45334, 45335, 45337, 45338, 45340, 45378, 45379, 45380, 45381, 45382, 45384, 45385, 45386, 45390, 45393, 45398, 91010, 91035, 91037, 91110, 99152, 99153, G0104, G0105, G0121, G0455
E12: Carrier(s): | I12: ALL
G13: Bill Type: | I13: Professional
D14: Cost Center(s): | H14: ALL
A15: Accounting Date From: | I15: 45566 | L15: To | N15: 45595
A17: Code | F17: Description | J17: Units | K17: Charges | M17: Payments | P17: Adjustments | R17: Refunds
A18: 99214 | F18: E/M Service Est Patient Level 4 | K18: =RANDBETWEEN(0,32500) -> 427 | M18: =RANDBETWEEN(0,7000) -> 1178 | P18: =RANDBETWEEN(0,25000) -> 421 | R18: =RANDBETWEEN(0,100) -> 18
A19: 99204 | F19: E/M Service New Patient Level 4 | K19: =RANDBETWEEN(0,32500) -> 15724 | M19: =RANDBETWEEN(0,7000) -> 5203 | P19: =RANDBETWEEN(0,25000) -> 17083 | R19: =RANDBETWEEN(0,100) -> 30
A20: 99233 | F20: Subsequent Hospital Care Level 3 | K20: =RANDBETWEEN(0,32500) -> 13885 | M20: =RANDBETWEEN(0,7000) -> 1296 | P20: =RANDBETWEEN(0,25000) -> 12727 | R20: =RANDBETWEEN(0,100) -> 10
A21: 99223 | F21: Initial Inpatient Hospital Care Level 3 | K21: =RANDBETWEEN(0,32500) -> 4988 | M21: =RANDBETWEEN(0,7000) -> 4360 | P21: =RANDBETWEEN(0,25000) -> 16875 | R21: =RANDBETWEEN(0,100) -> 62
A22: 99203 | F22: E/M Service New Patient Level 3 | K22: =RANDBETWEEN(0,32500) -> 3438 | M22: =RANDBETWEEN(0,7000) -> 6165 | P22: =RANDBETWEEN(0,25000) -> 7455 | R22: =RANDBETWEEN(0,100) -> 28
A23: 99222 | F23: 1st hosp ip/obs moderate 55 | K23: =RANDBETWEEN(0,32500) -> 877 | M23: =RANDBETWEEN(0,7000) -> 874 | P23: =RANDBETWEEN(0,25000) -> 1006 | R23: =RANDBETWEEN(0,100) -> 95
A24: 99213 | F24: E/M Service Est Patient Level 3 | K24: =RANDBETWEEN(0,32500) -> 21133 | M24: =RANDBETWEEN(0,7000) -> 5048 | P24: =RANDBETWEEN(0,25000) -> 3530 | R24: =RANDBETWEEN(0,100) -> 39
A25: 99254 | F25: Initial Inpatient Consult Level 4 | K25: =RANDBETWEEN(0,32500) -> 17039 | M25: =RANDBETWEEN(0,7000) -> 399 | P25: =RANDBETWEEN(0,25000) -> 9910 | R25: =RANDBETWEEN(0,100) -> 79
A26: 99214 | F26: E/M Service Est Patient Level 4 | K26: =RANDBETWEEN(0,32500) -> 10151 | M26: =RANDBETWEEN(0,7000) -> 4221 | P26: =RANDBETWEEN(0,25000) -> 4452 | R26: =RANDBETWEEN(0,100) -> 91
A27: 99213 | F27: E/M Service Est Patient Level 3 | K27: =RANDBETWEEN(0,32500) -> 22176 | M27: =RANDBETWEEN(0,7000) -> 4082 | P27: =RANDBETWEEN(0,25000) -> 21595 | R27: =RANDBETWEEN(0,100) -> 0
A28: S0285 | F28: office visit before a screening colonoscopy | K28: =RANDBETWEEN(0,32500) -> 28713 | M28: =RANDBETWEEN(0,7000) -> 1116 | P28: =RANDBETWEEN(0,25000) -> 16696 | R28: =RANDBETWEEN(0,100) -> 13
A29: 99204 | F29: E/M Service New Patient Level 4 | K29: =RANDBETWEEN(0,32500) -> 77 | M29: =RANDBETWEEN(0,7000) -> 3766 | P29: =RANDBETWEEN(0,25000) -> 3471 | R29: =RANDBETWEEN(0,100) -> 59
... A42: 99233 | F42: Subsequent Hospital Care Level 3 | K42: =RANDBETWEEN(0,32500) -> 30275 | M42: =RANDBETWEEN(0,7000) -> 5057 | P42: =RANDBETWEEN(0,25000) -> 181 | R42: =RANDBETWEEN(0,100) -> 79
A43: Total | K43: =SUM(K18:L42) -> 324339 | M43: =SUM(M18:O42) -> 81650 | P43: =SUM(P18:Q42) -> 261875 | R43: =SUM(R18:R42) -> 1265
A44: NOTE: Total for the services column may not match the sum of totals if multiple procedure codes are present on the same superbill (to avoid counting the same superbill twice)

Sheet November
A1: Procedure Code Frequency Report | AA1: =IF(ISBLANK(A17),0,INDEX(A:A:R:R,MATCH("Total",A:A,0),MATCH("Charges",A17:R17,0))) -> 406041
U2: Page 1 of 1 | AA2: =IF(ISBLANK(A17),0,INDEX(A:A:R:R,MATCH("Total",A:A,0),MATCH("Payments",A17:R17,0))) -> 73145
AA3: =IF(ISBLANK(A17),0,INDEX(A:A:R:R,MATCH("Total",A:A,0),MATCH("Refunds",A17:R17,0))) -> 1235
AA4: =AA2-AA3 -> 71910
A5: Business Unit:
A6: Performing Provider(s):
A7: Billing Provider(s): | I7: ALL
G8: Location(s): | I8: ALL
C9: Billing Group(s): | I9: ALL
C10: Payer Group(s): | I10: ALL
B11: CPT Code(s): | I11: 00731, 00811, 00812, 00813, 1000F, 1036F, 3017F, 4004F, 99201, 99202, 99203, 99204, 99205, 99211, 99212, 99213, 99214, 99215, 99219, 99222, 99223, 99224, 99225, 99231, 99232, 99233, 99234, 99235, 99236, 99238, 99241, 99242, 99243, 99244, 99245, 99251, 99252, 99253, 99254, 99255, 99281, 99282, 99283, 99284, 99285, 99291, 99292, S0285, SPL, 82150, 82397, 82784, 83690, 86140, 88312, 43200, 43226, 43235, 43236, 43239, 43241, 43244, 43245, 43246, 43247, 43248, 43249, 43250, 43251, 43255, 43260, 43261, 43262, 43264, 43265, 43274, 43275, 43277, 43450, 43762, 44360, 44361, 44363, 44364, 44365, 44366, 44378, 44380, 44386, 44388, 44389, 44390, 44391, 44392, 44394, 44705, 45305, 45330, 45331, 45332, 45333, 45334, 45335, 45337, 45338, 45340, 45378, 45379, 45380, 45381, 45382, 45384, 45385, 45386, 45390, 45393, 45398, 91010, 91035, 91037, 91110, 99152, 99153, G0104, G0105, G0121, G0455
E12: Carrier(s): | I12: ALL
G13: Bill Type: | I13: Professional
D14: Cost Center(s): | H14: ALL
A15: Accounting Date From: | I15: 45597 | L15: To | N15: 45626
A17: Code | F17: Description | J17: Units | K17: Charges | M17: Payments | P17: Adjustments | R17: Refunds
A18: 99214 | F18: E/M Service Est Patient Level 4 | K18: =RANDBETWEEN(0,32500) -> 1446 | M18: =RANDBETWEEN(0,7000) -> 3513 | P18: =RANDBETWEEN(0,25000) -> 3449 | R18: =RANDBETWEEN(0,100) -> 17
A19: 99204 | F19: E/M Service New Patient Level 4 | K19: =RANDBETWEEN(0,32500) -> 13428 | M19: =RANDBETWEEN(0,7000) -> 6081 | P19: =RANDBETWEEN(0,25000) -> 8626 | R19: =RANDBETWEEN(0,100) -> 66
A20: 99233 | F20: Subsequent Hospital Care Level 3 | K20: =RANDBETWEEN(0,32500) -> 17339 | M20: =RANDBETWEEN(0,7000) -> 2671 | P20: =RANDBETWEEN(0,25000) -> 253 | R20: =RANDBETWEEN(0,100) -> 6
A21: 99223 | F21: Initial Inpatient Hospital Care Level 3 | K21: =RANDBETWEEN(0,32500) -> 4869 | M21: =RANDBETWEEN(0,7000) -> 3732 | P21: =RANDBETWEEN(0,25000) -> 5455 | R21: =RANDBETWEEN(0,100) -> 4
A22: 99203 | F22: E/M Service New Patient Level 3 | K22: =RANDBETWEEN(0,32500) -> 9952 | M22: =RANDBETWEEN(0,7000) -> 4963 | P22: =RANDBETWEEN(0,25000) -> 19578 | R22: =RANDBETWEEN(0,100) -> 95
A23: 99222 | F23: 1st hosp ip/obs moderate 55 | K23: =RANDBETWEEN(0,32500) -> 24267 | M23: =RANDBETWEEN(0,7000) -> 1070 | P23: =RANDBETWEEN(0,25000) -> 1910 | R23: =RANDBETWEEN(0,100) -> 10
A24: 99213 | F24: E/M Service Est Patient Level 3 | K24: =RANDBETWEEN(0,32500) -> 12574 | M24: =RANDBETWEEN(0,7000) -> 4249 | P24: =RANDBETWEEN(0,25000) -> 20171 | R24: =RANDBETWEEN(0,100) -> 7
A25: 99254 | F25: Initial Inpatient Consult Level 4 | K25: =RANDBETWEEN(0,32500) -> 10770 | M25: =RANDBETWEEN(0,7000) -> 4255 | P25: =RANDBETWEEN(0,25000) -> 18299 | R25: =RANDBETWEEN(0,100) -> 50
A26: 99214 | F26: E/M Service Est Patient Level 4 | K26: =RANDBETWEEN(0,32500) -> 3351 | M26: =RANDBETWEEN(0,7000) -> 2745 | P26: =RANDBETWEEN(0,25000) -> 7956 | R26: =RANDBETWEEN(0,100) -> 72
A27: 99213 | F27: E/M Service Est Patient Level 3 | K27: =RANDBETWEEN(0,32500) -> 23381 | M27: =RANDBETWEEN(0,7000) -> 1960 | P27: =RANDBETWEEN(0,25000) -> 12587 | R27: =RANDBETWEEN(0,100) -> 73
A28: S0285 | F28: office visit before a screening colonoscopy | K28: =RANDBETWEEN(0,32500) -> 17480 | M28: =RANDBETWEEN(0,7000) -> 2224 | P28: =RANDBETWEEN(0,25000) -> 21661 | R28: =RANDBETWEEN(0,100) -> 100
A29: 99204 | F29: E/M Service New Patient Level 4 | K29: =RANDBETWEEN(0,32500) -> 6002 | M29: =RANDBETWEEN(0,7000) -> 4217 | P29: =RANDBETWEEN(0,25000) -> 16785 | R29: =RANDBETWEEN(0,100) -> 14
... A42: 99233 | F42: Subsequent Hospital Care Level 3 | K42: =RANDBETWEEN(0,32500) -> 32250 | M42: =RANDBETWEEN(0,7000) -> 1527 | P42: =RANDBETWEEN(0,25000) -> 10441 | R42: =RANDBETWEEN(0,100) -> 73
A43: Total | K43: =SUM(K18:L42) -> 406041 | M43: =SUM(M18:O42) -> 73145 | P43: =SUM(P18:Q42) -> 300434 | R43: =SUM(R18:R42) -> 1235
A44: NOTE: Total for the services column may not match the sum of totals if multiple procedure codes are present on the same superbill (to avoid counting the same superbill twice)

Sheet December
A1: Procedure Code Frequency Report | AA1: =IF(ISBLANK(A17),0,INDEX(A:A:R:R,MATCH("Total",A:A,0),MATCH("Charges",A17:R17,0))) -> 444337
U2: Page 1 of 1 | AA2: =IF(ISBLANK(A17),0,INDEX(A:A:R:R,MATCH("Total",A:A,0),MATCH("Payments",A17:R17,0))) -> 78865
AA3: =IF(ISBLANK(A17),0,INDEX(A:A:R:R,MATCH("Total",A:A,0),MATCH("Refunds",A17:R17,0))) -> 1439
AA4: =AA2-AA3 -> 77426
A5: Business Unit:
A6: Performing Provider(s):
A7: Billing Provider(s): | I7: ALL
G8: Location(s): | I8: ALL
C9: Billing Group(s): | I9: ALL
C10: Payer Group(s): | I10: ALL
B11: CPT Code(s): | I11: 00731, 00811, 00812, 00813, 1000F, 1036F, 3017F, 4004F, 99201, 99202, 99203, 99204, 99205, 99211, 99212, 99213, 99214, 99215, 99219, 99222, 99223, 99224, 99225, 99231, 99232, 99233, 99234, 99235, 99236, 99238, 99241, 99242, 99243, 99244, 99245, 99251, 99252, 99253, 99254, 99255, 99281, 99282, 99283, 99284, 99285, 99291, 99292, S0285, SPL, 82150, 82397, 82784, 83690, 86140, 88312, 43200, 43226, 43235, 43236, 43239, 43241, 43244, 43245, 43246, 43247, 43248, 43249, 43250, 43251, 43255, 43260, 43261, 43262, 43264, 43265, 43274, 43275, 43277, 43450, 43762, 44360, 44361, 44363, 44364, 44365, 44366, 44378, 44380, 44386, 44388, 44389, 44390, 44391, 44392, 44394, 44705, 45305, 45330, 45331, 45332, 45333, 45334, 45335, 45337, 45338, 45340, 45378, 45379, 45380, 45381, 45382, 45384, 45385, 45386, 45390, 45393, 45398, 91010, 91035, 91037, 91110, 99152, 99153, G0104, G0105, G0121, G0455
E12: Carrier(s): | I12: ALL
G13: Bill Type: | I13: Professional
D14: Cost Center(s): | H14: ALL
A15: Accounting Date From: | I15: 45627 | L15: To | N15: 45656
A17: Code | F17: Description | J17: Units | K17: Charges | M17: Payments | P17: Adjustments | R17: Refunds
A18: 99214 | F18: E/M Service Est Patient Level 4 | K18: =RANDBETWEEN(0,32500) -> 9887 | M18: =RANDBETWEEN(0,7000) -> 4963 | P18: =RANDBETWEEN(0,25000) -> 11909 | R18: =RANDBETWEEN(0,100) -> 72
A19: 99204 | F19: E/M Service New Patient Level 4 | K19: =RANDBETWEEN(0,32500) -> 9540 | M19: =RANDBETWEEN(0,7000) -> 6718 | P19: =RANDBETWEEN(0,25000) -> 18134 | R19: =RANDBETWEEN(0,100) -> 15
A20: 99233 | F20: Subsequent Hospital Care Level 3 | K20: =RANDBETWEEN(0,32500) -> 27431 | M20: =RANDBETWEEN(0,7000) -> 6422 | P20: =RANDBETWEEN(0,25000) -> 4535 | R20: =RANDBETWEEN(0,100) -> 88
A21: 99223 | F21: Initial Inpatient Hospital Care Level 3 | K21: =RANDBETWEEN(0,32500) -> 15457 | M21: =RANDBETWEEN(0,7000) -> 4953 | P21: =RANDBETWEEN(0,25000) -> 8179 | R21: =RANDBETWEEN(0,100) -> 37
A22: 99203 | F22: E/M Service New Patient Level 3 | K22: =RANDBETWEEN(0,32500) -> 6909 | M22: =RANDBETWEEN(0,7000) -> 3930 | P22: =RANDBETWEEN(0,25000) -> 1406 | R22: =RANDBETWEEN(0,100) -> 6
A23: 99222 | F23: 1st hosp ip/obs moderate 55 | K23: =RANDBETWEEN(0,32500) -> 24202 | M23: =RANDBETWEEN(0,7000) -> 2275 | P23: =RANDBETWEEN(0,25000) -> 23108 | R23: =RANDBETWEEN(0,100) -> 81
A24: 99213 | F24: E/M Service Est Patient Level 3 | K24: =RANDBETWEEN(0,32500) -> 2357 | M24: =RANDBETWEEN(0,7000) -> 4213 | P24: =RANDBETWEEN(0,25000) -> 12922 | R24: =RANDBETWEEN(0,100) -> 1
